<robot
  name="stand_alone_arm">
  
<link name="world" />

  <link
    name="base_link">
    <inertial>
      <origin
        xyz="3.33066907387547E-16 0.669683979678505 -0.0124306420707494"
        rpy="1.5708 0 0" />
      <mass
        value="858.041961090524" />
      <inertia
        ixx="95.273734367112"
        ixy="1.68979319427503E-13"
        ixz="9.07122406083939E-15"
        iyy="340.274147568561"
        iyz="3.19643307330068"
        izz="305.046621365407" />
    </inertial>
    <visual>
      <origin
        xyz="0 0 0"
        rpy="0 0 0" />
      <geometry>
        <mesh
          filename="package://fetch_description/meshes/table_link.DAE" />
      </geometry>
      <material
        name="">
        <color
          rgba="0.529411764705882 0.549019607843137 0.549019607843137 1" />
      </material>
    </visual>
    <collision>
      <origin
        xyz="0 0 0"
        rpy="0 0 0" />
      <geometry>
        <mesh
          filename="package://fetch_description/meshes/table_link.STL" />
      </geometry>
    </collision>
  </link>

  <joint
    name="table_joint"
    type="fixed">
    <origin
      xyz="0 0 0"
      rpy="1.5708 0 0" />
    <parent
      link="world" />
    <child
      link="base_link" />
    <axis
      xyz="0 0 0" />
  </joint>

  <link
    name="stand_alone_base_link">
    <inertial>
      <origin
        xyz="0 0 -0.105150405821854"
        rpy="0 0 0" />
      <mass
        value="2.63878043891333" />
      <inertia
        ixx="0.00472313159089556"
        ixy="6.11678055813915E-20"
        ixz="5.52853966202781E-19"
        iyy="0.00472313159089556"
        iyz="2.17976604623059E-19"
        izz="0.00382379229994236" />
    </inertial>
    <visual>
      <origin
        xyz="0 0 0"
        rpy="0 0 0" />
      <geometry>
        <mesh
          filename="package://fetch_description/meshes/stand_alone_base_link.STL" />
      </geometry>
      <material
        name="">
        <color
          rgba="1 1 1 1" />
      </material>
    </visual>
    <collision>
      <origin
        xyz="0 0 0"
        rpy="0 0 0" />
      <geometry>
        <mesh
          filename="package://fetch_description/meshes/stand_alone_base_link.STL" />
      </geometry>
    </collision>
  </link>

  <joint
    name="stand_alone_base_joint"
    type="fixed">
    <origin
      xyz="0.203950000000001 0 0.948"
      rpy="0 0 -1.5708" />
    <parent
      link="world" />
    <child
      link="stand_alone_base_link" />
    <axis
      xyz="0 0 0" />
  </joint>

 <link name="shoulder_pan_link">
    <inertial>
      <origin rpy="0.6737277 -030216635 0.04986231" xyz="0 0 0" />
      <mass value="2.5587" />
      <inertia ixx="0.0043" ixy="-0.0001" ixz="0.001" iyy="0.0087" iyz="-0.0001" izz="0.0087" />
    </inertial>
    <visual>
      <origin rpy="0 0 0" xyz="0 0 0" />
      <geometry>
        <mesh filename="package://fetch_description/meshes/shoulder_pan_link.dae" />
      </geometry>
      <material name="">
        <color rgba="1 1 1 1" />
      </material>
    </visual>
    <collision>
      <origin rpy="0 0 0" xyz="0 0 0" />
      <geometry>
        <mesh filename="package://fetch_description/meshes/shoulder_pan_link_collision.STL" />
      </geometry>
    </collision>
  </link>
  
<joint name="shoulder_pan_joint" type="revolute">
    <origin rpy="0 0 -1.5708" xyz="0 0 0" />
    <parent link="stand_alone_base_link" />
    <child link="shoulder_pan_link" />
    <axis xyz="0 0 1" />
    <dynamics damping="1.0" />
    <limit effort="33.82" lower="-1.6056" upper="1.6056" velocity="1.256" />
</joint>


 <link name="shoulder_lift_link">
    <inertial>
      <origin rpy="0 0 0" xyz="0.1432 0.0072 -0.0001" />
      <mass value="2.6615" />
      <inertia ixx="0.0028" ixy="-0.0021" ixz="-0.0" iyy="0.0111" iyz="-0.0" izz="0.0112" />
    </inertial>
    <visual>
      <origin rpy="0 0 0" xyz="0 0 0" />
      <geometry>
        <mesh filename="package://fetch_description/meshes/shoulder_lift_link.dae" />
      </geometry>
      <material name="">
        <color rgba="0.086 0.506 0.767 1" />
      </material>
    </visual>
    <collision>
      <origin rpy="0 0 0" xyz="0 0 0" />
      <geometry>
        <mesh filename="package://fetch_description/meshes/shoulder_lift_link_collision.STL" />
      </geometry>
    </collision>
  </link>

  <joint name="shoulder_lift_joint" type="revolute">
    <origin rpy="0 0 0" xyz="0.117 0 0.0599999999999999" />
    <parent link="shoulder_pan_link" />
    <child link="shoulder_lift_link" />
    <axis xyz="0 1 0" />
    <dynamics damping="1.0" />
    <limit effort="131.76" lower="-1.221" upper="1.518" velocity="1.454" />
  </joint>
  <link name="upperarm_roll_link">
    <inertial>
      <origin rpy="0 0 0" xyz="0.1165 0.0014 0.0000" />
      <mass value="2.3311" />
      <inertia ixx="0.0019" ixy="-0.0001" ixz="0.0" iyy="0.0045" iyz="0.0" izz="0.0047" />
    </inertial>
    <visual>
      <origin rpy="0 0 0" xyz="0 0 0" />
      <geometry>
        <mesh filename="package://fetch_description/meshes/upperarm_roll_link.dae" />
      </geometry>
      <material name="">
        <color rgba="1 1 1 1" />
      </material>
    </visual>
    <collision>
      <origin rpy="0 0 0" xyz="0 0 0" />
      <geometry>
        <mesh filename="package://fetch_description/meshes/upperarm_roll_link_collision.STL" />
      </geometry>
    </collision>
  </link>

  <joint name="upperarm_roll_joint" type="continuous">
    <origin rpy="0 0 0" xyz="0.219 0 0" />
    <parent link="shoulder_lift_link" />
    <child link="upperarm_roll_link" />
    <axis xyz="1 0 0" />
    <dynamics damping="5.0" />
    <limit effort="76.94" velocity="1.571" />
  </joint>

  <link name="elbow_flex_link">
    <inertial>
      <origin rpy="0 0 0" xyz="0.1279 0.0073 0.0000" />
      <mass value="2.1299" />
      <inertia ixx="0.0024" ixy="-0.0016" ixz="0.0" iyy="0.0082" iyz="-0.0" izz="0.0084" />
    </inertial>
    <visual>
      <origin rpy="0 0 0" xyz="0 0 0" />
      <geometry>
        <mesh filename="package://fetch_description/meshes/elbow_flex_link.dae" />
      </geometry>
      <material name="">
        <color rgba="0.086 0.506 0.767 1" />
      </material>
    </visual>
    <collision>
      <origin rpy="0 0 0" xyz="0 0 0" />
      <geometry>
        <mesh filename="package://fetch_description/meshes/elbow_flex_link_collision.STL" />
      </geometry>
    </collision>
  </link>

  <joint name="elbow_flex_joint" type="revolute">
    <origin rpy="0 0 0" xyz="0.133 0 0" />
    <parent link="upperarm_roll_link" />
    <child link="elbow_flex_link" />
    <axis xyz="0 1 0" />
    <dynamics damping="1.0" />
    <limit effort="66.18" lower="-2.251" upper="2.251" velocity="1.521" />
  </joint>

  <link name="forearm_roll_link">
    <inertial>
      <origin rpy="0 0 0" xyz="0.1097 -0.00 0.0000" />
      <mass value="1.6563" />
      <inertia ixx="0.0016" ixy="-0.0003" ixz="0.0" iyy="0.003" iyz="-0.0" izz="0.0035" />
    </inertial>
    <visual>
      <origin rpy="0 0 0" xyz="0 0 0" />
      <geometry>
        <mesh filename="package://fetch_description/meshes/forearm_roll_link.dae" />
      </geometry>
      <material name="">
        <color rgba="1 1 1 1" />
      </material>
    </visual>
    <collision>
      <origin rpy="0 0 0" xyz="0 0 0" />
      <geometry>
        <mesh filename="package://fetch_description/meshes/forearm_roll_link_collision.STL" />
      </geometry>
    </collision>
  </link>

  <joint name="forearm_roll_joint" type="continuous">
    <origin rpy="0 0 0" xyz="0.197 0 0" />
    <parent link="elbow_flex_link" />
    <child link="forearm_roll_link" />
    <axis xyz="1 0 0" />
    <dynamics damping="5.0" />
    <limit effort="29.35" velocity="1.571" />
  </joint>


  <link name="wrist_flex_link">
    <inertial>
      <origin rpy="0 0 0" xyz="0.0882 0.0009 -0.0001" />
      <mass value="1.725" />
      <inertia ixx="0.0018" ixy="-0.0001" ixz="-0.0" iyy="0.0042" iyz="0.0" izz="0.0042" />
    </inertial>
    <visual>
      <origin rpy="0 0 0" xyz="0 0 0" />
      <geometry>
        <mesh filename="package://fetch_description/meshes/wrist_flex_link.dae" />
      </geometry>
      <material name="">
        <color rgba="0.086 0.506 0.767 1" />
      </material>
    </visual>
    <collision>
      <origin rpy="0 0 0" xyz="0 0 0" />
      <geometry>
        <mesh filename="package://fetch_description/meshes/wrist_flex_link_collision.STL" />
      </geometry>
    </collision>
  </link>

  <joint name="wrist_flex_joint" type="revolute">
    <origin rpy="0 0 0" xyz="0.1245 0 0" />
    <parent link="forearm_roll_link" />
    <child link="wrist_flex_link" />
    <axis xyz="0 1 0" />
    <dynamics damping="1.0" />
    <limit effort="25.7" lower="-2.16" upper="2.16" velocity="2.268" />
  </joint>


  <link name="wrist_roll_link">
    <inertial>
      <origin rpy="0 0 0" xyz="0.0095 0.0004 -0.0002" />
      <mass value="0.1354" />
      <inertia ixx="0.0001" ixy="0.0" ixz="0.0" iyy="0.0001" iyz="0.0" izz="0.0001" />
    </inertial>
    <visual>
      <origin rpy="0 0 0" xyz="0 0 0" />
      <geometry>
        <mesh filename="package://fetch_description/meshes/wrist_roll_link.dae" />
      </geometry>
      <material name="">
        <color rgba="1 1 1 1" />
      </material>
    </visual>
    <collision>
      <origin rpy="0 0 0" xyz="0 0 0" />
      <geometry>
        <mesh filename="package://fetch_description/meshes/wrist_roll_link_collision.STL" />
      </geometry>
    </collision>
  </link>

  <joint name="wrist_roll_joint" type="continuous">
    <origin rpy="0 0 0" xyz="0.1385 0 0" />
    <parent link="wrist_flex_link" />
    <child link="wrist_roll_link" />
    <axis xyz="1 0 0" />
    <limit effort="7.36" velocity="2.268" />
    <dynamics damping="5.0" />
  </joint>


  <link name="gripper_link">
    <inertial>
      <origin rpy="0 0 0" xyz="-0.0900 -0.0001 -0.0017" />
      <mass value="1.5175" />
      <inertia ixx="0.0013" ixy="-0.0" ixz="0.0" iyy="0.0019" iyz="-0.0" izz="0.0024" />
    </inertial>
    <visual>
      <origin rpy="0 0 0" xyz="0 0 0" />
      <geometry>
        <mesh filename="package://fetch_description/meshes/gripper_link.dae" />
      </geometry>
    </visual>
    <collision>
      <origin rpy="0 0 0" xyz="0 0 0" />
      <geometry>
        <mesh filename="package://fetch_description/meshes/gripper_link.STL" />
      </geometry>
    </collision>
  </link>
  <joint name="gripper_axis" type="fixed">
    <origin rpy="0 0 0" xyz="0.16645 0 0" />
    <parent link="wrist_roll_link" />
    <child link="gripper_link" />
    <axis xyz="0 1 0" />

  </joint>
  <link name="r_gripper_finger_link">
    <inertial>
      <origin rpy="0 0 0" xyz="-0.01 0 0" />
      <mass value="0.0798" />
      <inertia ixx="0.002" ixy="0" ixz="0" iyy="0" iyz="0" izz="0" />
    </inertial>
    <visual>
      <origin rpy="0 0 0" xyz="0 0.101425 0" />
      <geometry>
        <mesh filename="package://fetch_description/meshes/r_gripper_finger_link.STL" />
      </geometry>
      <material name="">
        <color rgba="0.356 0.361 0.376 1" />
      </material>
    </visual>
    <collision>
      <origin rpy="0 0 0" xyz="0 0.101425 0" />
      <geometry>
        <mesh filename="package://fetch_description/meshes/r_gripper_finger_link.STL" />
      </geometry>
    </collision>
  </link>
  <joint name="r_gripper_finger_joint" type="prismatic">
    <origin rpy="0 0 0" xyz="0 0.015425 0" />
    <parent link="gripper_link" />
    <child link="r_gripper_finger_link" />
    <axis xyz="0 1 0" />
  <limit effort="60" lower="0.0" upper="0.05" velocity="0.05" /><dynamics damping="100.0" />
  </joint>

  <link name="l_gripper_finger_link">
    <inertial>
      <origin rpy="0 0 0" xyz="-0.01 0 0" />
      <mass value="0.0798" />
      <inertia ixx="0.002" ixy="0" ixz="0" iyy="0" iyz="0" izz="0" />
    </inertial>
    <visual>
      <origin rpy="0 0 0" xyz="0 -0.101425 0" />
      <geometry>
        <mesh filename="package://fetch_description/meshes/l_gripper_finger_link.STL" />
      </geometry>
      <material name="">
        <color rgba="0.356 0.361 0.376 1" />
      </material>
    </visual>
    <collision>
      <origin rpy="0 0 0" xyz="0 -0.101425 0" />
      <geometry>
        <mesh filename="package://fetch_description/meshes/l_gripper_finger_link.STL" />
      </geometry>
    </collision>
  </link>
  <joint name="l_gripper_finger_joint" type="prismatic">
    <origin rpy="0 0 0" xyz="0 -0.015425 0" />
    <parent link="gripper_link" />
    <child link="l_gripper_finger_link" />
    <axis xyz="0 -1 0" />
  <limit effort="60" lower="0.0" upper="0.05" velocity="0.05" /><dynamics damping="100.0" />
   </joint>

  <link
    name="gantry_link">
    <inertial>
      <origin
        xyz="1.38777878078145E-17 1.09321662265258 0.198951164372599"
        rpy="0 0 0" />
      <mass
        value="7.4976" />
      <inertia
        ixx="2.75442106479115"
        ixy="9.90440054718383E-17"
        ixz="3.9473035636081E-17"
        iyy="0.717328512218835"
        iyz="0.709705248466385"
        izz="2.03897463257232" />
    </inertial>
    <visual>
      <origin
        xyz="0 0 0"
        rpy="0 0 0" />
      <geometry>
        <mesh
          filename="package://fetch_description/meshes/gantry_link.STL" />
      </geometry>
      <material
        name="">
        <color
          rgba="0.792156862745098 0.819607843137255 0.933333333333333 1" />
      </material>
    </visual>
    <collision>
      <origin
        xyz="0 0 0"
        rpy="0 0 0" />
      <geometry>
        <mesh
          filename="package://fetch_description/meshes/gantry_link.STL" />
      </geometry>
    </collision>
  </link>
  <joint
    name="gantry_joint"
    type="fixed">
    <origin
      xyz="0.688950000000001 0.79 0"
      rpy="0 -1.5708 0" />
    <parent
      link="base_link" />
    <child
      link="gantry_link" />
    <axis
      xyz="0 0 0" />
  </joint>
  <link
    name="camera_link">
    <inertial>
      <origin
        xyz="-0.000145676872565954 0.0286871507440698 0.000951150405185119"
        rpy="0 0 0" />
      <mass
        value="0.355265785482826" />
      <inertia
        ixx="0.000326426184711212"
        ixy="-2.44193073100511E-06"
        ixz="4.82333863656688E-08"
        iyy="0.000260785095247953"
        iyz="-1.01246164864081E-06"
        izz="0.000308498594625202" />
    </inertial>
    <visual>
      <origin
        xyz="0 0 0"
        rpy="0 0 0" />
      <geometry>
        <mesh
          filename="package://fetch_description/meshes/camera.DAE" />
      </geometry>
      <material
        name="">
        <color
          rgba="0 0 0 1" />
      </material>
    </visual>
    <collision>
      <origin
        xyz="0 0 0"
        rpy="0 0 0" />
      <geometry>
        <mesh
          filename="package://fetch_description/meshes/camera_link.STL" />
      </geometry>
    </collision>
  </link>
  <joint
    name="camera_joint"
    type="fixed">
    <origin
      xyz="0 1.5233 1.049"
      rpy="0 0 -1.570" />
    <parent
      link="gantry_link" />
    <child
      link="camera_link" />
    <axis
      xyz="0 0 0" />
  </joint>

  <link name="camera_optical_link" />
  <joint name="camera_optical_joint" type="fixed">
    <origin rpy="0 0 -1.570" xyz="-0.00 -0.0093 -.0" />
    <parent link="camera_link" />
    <child link="camera_optical_link" />
  </joint>

  <link name="camera_rgb_frame" />
  <joint name="camera_rgb_joint" type="fixed">
    <origin rpy="0 0 0" xyz="0 -0.0093 0" />
    <parent link="camera_link" />
    <child link="camera_rgb_frame" />
  </joint>
  <link name="camera_rgb_optical_frame" />
  <joint name="camera_rgb_optical_joint" type="fixed">
    <origin rpy="0 0 0" xyz="0 -0.0093 0" />
    <parent link="camera_link" />
    <child link="camera_rgb_optical_frame" />
  </joint>
  <link name="camera_depth_frame" />
  <joint name="camera_depth_joint" type="fixed">
    <origin rpy="0 0 0" xyz="0 -0.0093 0" />
    <parent link="camera_link" />
    <child link="camera_depth_frame" />
  </joint>
  <link name="camera_depth_optical_frame" />
  <joint name="camera_depth_optical_joint" type="fixed">
    <origin rpy="0 0 0" xyz="0 -0.0093 0" />
    <parent link="camera_link" />
    <child link="camera_depth_optical_frame" />
  </joint>



   <link
    name="wall_link">
    <inertial>
      <origin
        xyz="-2.22044604925031E-16 1.2192 0"
        rpy="0 0 0" />
      <mass
        value="243.839999999999" />
      <inertia
        ixx="120.8510574592"
        ixy="1.71905156776115E-15"
        ixz="-1.65907426685763E-14"
        iyy="127.032512"
        iyz="7.22801448323673E-17"
        izz="247.818545459199" />
    </inertial>
    <visual>
      <origin
        xyz="0 0 0"
        rpy="0 0 0" />
      <geometry>
        <mesh
          filename="package://fetch_description/meshes/wall_link.DAE" />
      </geometry>
      <material
        name="">
        <color
          rgba="0.792156862745098 0.819607843137255 0.933333333333333 1" />
      </material>
    </visual>
    <collision>
      <origin
        xyz="0 0 0"
        rpy="0 0 0" />
      <geometry>
        <mesh
          filename="package://fetch_description/meshes/wall_link.STL" />
      </geometry>
    </collision>
  </link>
  <joint
    name="wall_joint"
    type="fixed">
    <origin
      xyz="-0.034999999999999 0 -0.8775"
      rpy="0 0 0" />
    <parent
      link="base_link" />
    <child
      link="wall_link" />
    <axis
      xyz="0 0 0" />
  </joint>
</robot>
  
